{"uuid": "c17cfef4-3b00-4928-aed7-9f7c76363cdc", "children": ["d0f1afcb-3cc3-4438-b9c1-9a43420af347", "067bee45-48b4-4ba0-8440-3c08c577a617"], "befores": [{"name": "beforeClass", "status": "broken", "statusDetails": {"message": "urllib3.exceptions.MaxRetryError: HTTPConnectionPool(host='127.0.0.1', port=4723): Max retries exceeded with url: /wd/hub/session (Caused by NewConnectionError('<urllib3.connection.HTTPConnection object at 0x000001CF5484FC10>: Failed to establish a new connection: [WinError 10061] No connection could be made because the target machine actively refused it'))\n", "trace": "  File \"C:\\Python39\\lib\\site-packages\\pluggy\\_callers.py\", line 39, in _multicall\n    res = hook_impl.function(*args)\n  File \"C:\\Python39\\lib\\site-packages\\_pytest\\fixtures.py\", line 1121, in pytest_fixture_setup\n    result = call_fixture_func(fixturefunc, request, kwargs)\n  File \"C:\\Python39\\lib\\site-packages\\_pytest\\fixtures.py\", line 893, in call_fixture_func\n    fixture_result = next(generator)\n  File \"C:\\Users\\Ibrahem Taha\\PycharmProjects\\AppiumGoogleNotes\\tests\\conftest.py\", line 9, in beforeClass\n    driver = driver1.getDriverMethod()\n  File \"D:\\pycharmProjects\\AppiumGoogleNotes\\base\\DriverClass.py\", line 15, in getDriverMethod\n    driver = webdriver.Remote('http://127.0.0.1:4723/wd/hub', desired_caps)\n  File \"C:\\Python39\\lib\\site-packages\\appium\\webdriver\\webdriver.py\", line 230, in __init__\n    super().__init__(\n  File \"C:\\Python39\\lib\\site-packages\\selenium\\webdriver\\remote\\webdriver.py\", line 270, in __init__\n    self.start_session(capabilities, browser_profile)\n  File \"C:\\Python39\\lib\\site-packages\\appium\\webdriver\\webdriver.py\", line 320, in start_session\n    response = self.execute(RemoteCommand.NEW_SESSION, w3c_caps)\n  File \"C:\\Python39\\lib\\site-packages\\selenium\\webdriver\\remote\\webdriver.py\", line 426, in execute\n    response = self.command_executor.execute(driver_command, params)\n  File \"C:\\Python39\\lib\\site-packages\\selenium\\webdriver\\remote\\remote_connection.py\", line 344, in execute\n    return self._request(command_info[0], url, body=data)\n  File \"C:\\Python39\\lib\\site-packages\\selenium\\webdriver\\remote\\remote_connection.py\", line 366, in _request\n    response = self._conn.request(method, url, body=body, headers=headers)\n  File \"C:\\Python39\\lib\\site-packages\\urllib3\\request.py\", line 78, in request\n    return self.request_encode_body(\n  File \"C:\\Python39\\lib\\site-packages\\urllib3\\request.py\", line 170, in request_encode_body\n    return self.urlopen(method, url, **extra_kw)\n  File \"C:\\Python39\\lib\\site-packages\\urllib3\\poolmanager.py\", line 375, in urlopen\n    response = conn.urlopen(method, u.request_uri, **kw)\n  File \"C:\\Python39\\lib\\site-packages\\urllib3\\connectionpool.py\", line 783, in urlopen\n    return self.urlopen(\n  File \"C:\\Python39\\lib\\site-packages\\urllib3\\connectionpool.py\", line 783, in urlopen\n    return self.urlopen(\n  File \"C:\\Python39\\lib\\site-packages\\urllib3\\connectionpool.py\", line 783, in urlopen\n    return self.urlopen(\n  File \"C:\\Python39\\lib\\site-packages\\urllib3\\connectionpool.py\", line 755, in urlopen\n    retries = retries.increment(\n  File \"C:\\Python39\\lib\\site-packages\\urllib3\\util\\retry.py\", line 574, in increment\n    raise MaxRetryError(_pool, url, error or ResponseError(cause))\n"}, "start": 1665290020572, "stop": 1665290028653}], "start": 1665290020572, "stop": 1665290029012}